Workbook

Sheet Task-1
A1: PostID | B1: Platform | C1: Date | D1: Hashtags | E1: Likes | F1: Shares | G1: Comments | H1: Clicks | I1: Reach | J1: Impressions
A2: A1 | B2: YouTube | C2: 45649 | D2: #AppleWatchUltra2, #HealthTech | E2: 24516 | F2: 976 | G2: 974 | H2: 2675 | I2: 23275 | J2: 202932
A3: A2 | B3: LinkedIn | C3: 45903 | D3: #MacBookAirM3, #AppleInnovation | E3: 4779 | F3: 1110 | G3: 436 | H3: 1574 | I3: 77167 | J3: 71585
A4: A3 | B4: Instagram | C4: 45789 | D4: #AppleDesign, #Innovation | E4: 19308 | F4: 1318 | G4: 795 | H4: 1499 | I4: 52307 | J4: 193087
A5: A4 | B5: YouTube | C5: 45516 | D5: #AppleEvent, #iPadPro | E5: 3581 | F5: 517 | G5: 880 | H5: 1925 | I5: 18636 | J5: 248611 | L5: Task 1: Data Preprocessing & Cleaning (12 Marks)
A6: A5 | B6: YouTube | C6: 45904 | D6: #AppleWatchUltra2, #HealthTech | E6: 21708 | F6: 435 | G6: 317 | H6: 1213 | I6: 70701 | J6: 83585 | L6: ● Remove duplicate Tesla posts.
A7: A6 | B7: LinkedIn | C7: 45905 | D7: #ShotOniPhone | E7: 14677 | F7: 533 | G7: 759 | H7: 753 | I7: 23275 | J7: 66958 | L7: ● Standardize date & platform names.
A8: A7 | B8: Instagram | C8: 45467 | D8: #AppleMusic, #AppleLifestyle | E8: 7713 | F8: 575 | G8: 417 | H8: 336 | I8: 61660 | J8: 66017 | L8: ● Format numeric columns (Likes, Reach, Impressions, Ad Spend).
A9: A8 | B9: Instagram | C9: 45486 | D9: #AppleWatch, #Health | E9: 18639 | F9: 1360 | G9: 898 | H9: 2011 | I9: 42841 | J9: 247779 | L9: ● Split hashtags (e.g., #ShotOniPhone, #iPhone16, #AppleEvent) into separate tags for
A10: A9 | B10: YouTube | C10: 45534 | D10: #MacBookAirM3, #AppleInnovation | E10: 6804 | F10: 787 | G10: 970 | H10: 1095 | I10: 56343 | J10: 164677 | L10: analysis.
A11: A10 | B11: Twitter | C11: 45727 | D11: #iPhone16Launch, #AppleEvent | E11: 20222 | F11: 712 | G11: 604 | H11: 1272 | I11: 71598 | J11: 216422
A12: A11 | B12: YouTube | C12: 45690 | D12: #AppleEvent, #iPadPro | E12: 12136 | F12: 1117 | G12: 834 | H12: 892 | I12: 24675 | J12: 183273 | L12: Power query is used in the post dataset which is cleaned. Copied
A13: A12 | B13: YouTube | C13: 45494 | D13: #MacBookAirM3, #AppleInnovation | E13: 2009 | F13: 1072 | G13: 550 | H13: 1437 | I13: 22982 | J13: 69426 | L13: Also, I have formatted datas. Date format is done. Likes,shares ,etc in number format with comma(,). No duplicate is found. Spitted the hashtags with Find and replace method
A14: A13 | B14: YouTube | C14: 45614 | D14: #AppleMusic, #AppleLifestyle | E14: 21255 | F14: 1452 | G14: 625 | H14: 1624 | I14: 21282 | J14: 57778
A15: A14 | B15: YouTube | C15: 45906 | D15: #AppleWatch, #Health | E15: 7124 | F15: 469 | G15: 851 | H15: 2571 | I15: 33802 | J15: 216313
A16: A15 | B16: LinkedIn | C16: 45907 | D16: #AppleDesign, #Innovation | E16: 3015 | F16: 997 | G16: 783 | H16: 617 | I16: 77167 | J16: 82229
A17: A16 | B17: Instagram | C17: 45530 | D17: #AppleWatch, #Health | E17: 4193 | F17: 924 | G17: 707 | H17: 2696 | I17: 55075 | J17: 126652
A18: A17 | B18: LinkedIn | C18: 45782 | D18: #AppleEvent, #iPhone16 | E18: 10415 | F18: 1388 | G18: 725 | H18: 2462 | I18: 53082 | J18: 168267
A19: A18 | B19: LinkedIn | C19: 45523 | D19: #AppleWatch, #Health | E19: 15550 | F19: 204 | G19: 279 | H19: 1646 | I19: 35819 | J19: 219436
A20: A19 | B20: LinkedIn | C20: 45466 | D20: #AppleEvent, #iPhone16 | E20: 16512 | F20: 1050 | G20: 971 | H20: 1891 | I20: 15865 | J20: 166503
A21: A20 | B21: YouTube | C21: 45544 | D21: #AppleDesign, #Innovation | E21: 6158 | F21: 277 | G21: 512 | H21: 2189 | I21: 76881 | J21: 124878
A22: A21 | B22: Twitter | C22: 45908 | D22: #iPhonePhotography, #ShotOniPhone | E22: 22309 | F22: 773 | G22: 854 | H22: 2387 | I22: 72396 | J22: 97056
A23: A22 | B23: Instagram | C23: 45715 | D23: #AppleMusic, #AppleLifestyle | E23: 8970 | F23: 331 | G23: 968 | H23: 2296 | I23: 24613 | J23: 198562
A24: A23 | B24: Twitter | C24: 45602 | D24: #AppleEvent, #iPhone16 | E24: 8938 | F24: 800 | G24: 842 | H24: 2072 | I24: 31736 | J24: 59975
A25: A24 | B25: LinkedIn | C25: 45680 | D25: #iPhone16Launch, #AppleEvent | E25: 23168 | F25: 1265 | G25: 441 | H25: 1612 | I25: 66615 | J25: 197795
... A301: A300 | B301: LinkedIn | C301: 45926 | D301: #iPhone16Launch, #AppleEvent | E301: 21216 | F301: 226 | G301: 187 | H301: 1573 | I301: 62688 | J301: 111031

Sheet Task1_Cleaned_Posts
A1: PostID | B1: Platform | C1: Date | D1: ContentType | E1: Hashtags | F1: Likes | G1: Shares | H1: Comments | I1: Clicks | J1: Reach | K1: Impressions | L1: EngagementRate | M1: Campaign
A2: A82 | B2: LinkedIn | C2: 45497 | D2: Video | E2: #AppleMusic, #AppleLifestyle | F2: 22914 | G2: 954 | H2: 584 | I2: 1519 | J2: 13637 | K2: 49847 | L2: 0.49054106 | M2: Apple Watch Ultra 2 Launch | O2: Task 1: Data Preprocessing & Cleaning
A3: A201 | B3: YouTube | C3: 45672 | D3: Tweet | E3: #ShotOniPhone | F3: 20360 | G3: 254 | H3: 726 | I3: 1995 | J3: 14280 | K3: 43726 | L3: 0.48803915 | M3: iPhone 16 Launch | O3: ● Remove duplicate Apple posts.
A4: A121 | B4: LinkedIn | C4: 45502 | D4: Video | E4: #AppleWatchUltra2, #HealthTech | F4: 19144 | G4: 1182 | H4: 860 | I4: 1398 | J4: 4185 | K4: 46570 | L4: 0.45492807 | M4: Apple Watch Ultra 2 Launch | O4: ● Standardize date & platform names.
A5: A127 | B5: Twitter | C5: 45684 | D5: Image | E5: #AppleEvent, #iPhone16 | F5: 24415 | G5: 860 | H5: 931 | I5: 320 | J5: 65049 | K5: 62911 | L5: 0.41655672 | M5: Apple Watch Ultra 2 Launch | O5: ● Format numeric columns (Likes, Reach, Impressions, Ad Spend).
A6: A13 | B6: YouTube | C6: 45614 | D6: Carousel | E6: #AppleMusic, #AppleLifestyle | F6: 21255 | G6: 1452 | H6: 625 | I6: 1624 | J6: 21282 | K6: 57778 | L6: 0.40382152 | M6: MacBook Air M3 Campaign | O6: ● Split hashtags (e.g., #ShotOniPhone, #iPhone16, #AppleEvent) into separate tags for
A7: A123 | B7: Twitter | C7: 45457 | D7: Video | E7: #AppleEvent, #iPhone16 | F7: 17183 | G7: 1224 | H7: 943 | I7: 2010 | J7: 21481 | K7: 49110 | L7: 0.39401344 | M7: Sustainability Awareness Drive | O7: analysis.
A8: A287 | B8: Instagram | C8: 45519 | D8: Video | E8: #AppleEvent, #iPadPro | F8: 14977 | G8: 274 | H8: 798 | I8: 458 | J8: 6636 | K8: 43654 | L8: 0.367641 | M8: Apple Watch Ultra 2 Launch
A9: A226 | B9: Twitter | C9: 45908 | D9: Tweet | E9: #AppleWatch, #Health | F9: 23785 | G9: 1013 | H9: 468 | I9: 1628 | J9: 8272 | K9: 71348 | L9: 0.35412345 | M9: Apple Event September 2025 | O9: Power query is used in the post dataset which is cleaned
A10: A231 | B10: Twitter | C10: 45909 | D10: Image | E10: #AppleMusic, #AppleLifestyle | F10: 19260 | G10: 668 | H10: 994 | I10: 934 | J10: 20509 | K10: 61636 | L10: 0.33944448 | M10: Apple Event September 2025 | O10: Also, I have formatted datas. Date format is done. Likes,shares ,etc in number format with comma(,).
A11: A185 | B11: Instagram | C11: 45668 | D11: Image | E11: #MacBookAirM3, #AppleInnovation | F11: 21181 | G11: 1242 | H11: 963 | I11: 1689 | J11: 49329 | K11: 69165 | L11: 0.33811899 | M11: Apple Watch Ultra 2 Launch | O11: No duplicate is found. Splitted the hashtags with Find and replace method.
A12: A106 | B12: Twitter | C12: 45692 | D12: Carousel | E12: #AppleWatch, #Health | F12: 23833 | G12: 555 | H12: 523 | I12: 1330 | J12: 69141 | K12: 73997 | L12: 0.33664878 | M12: iPhone 16 Launch
A13: A174 | B13: LinkedIn | C13: 45465 | D13: Carousel | E13: #AppleWatchUltra2, #HealthTech | F13: 13479 | G13: 1189 | H13: 695 | I13: 416 | J13: 30229 | K13: 45704 | L13: 0.33614126 | M13: Apple Watch Ultra 2 Launch
A14: A254 | B14: Instagram | C14: 45671 | D14: Carousel | E14: #AppleEvent, #iPhone16 | F14: 24350 | G14: 460 | H14: 666 | I14: 814 | J14: 21120 | K14: 76914 | L14: 0.33122708 | M14: Apple Watch Ultra 2 Launch
A15: A223 | B15: Twitter | C15: 45608 | D15: Video | E15: #AppleDesign, #Innovation | F15: 17913 | G15: 1311 | H15: 859 | I15: 405 | J15: 59842 | K15: 62612 | L15: 0.32075321 | M15: Sustainability Awareness Drive
A16: A164 | B16: LinkedIn | C16: 45715 | D16: Image | E16: #MacBookAirM3, #AppleInnovation | F16: 16178 | G16: 1048 | H16: 871 | I16: 2553 | J16: 39025 | K16: 59508 | L16: 0.30411037 | M16: Apple Watch Ultra 2 Launch
A17: A151 | B17: YouTube | C17: 45499 | D17: Video | E17: #MacBookProM3 | F17: 18282 | G17: 224 | H17: 962 | I17: 890 | J17: 35105 | K17: 64089 | L17: 0.30376508 | M17: iPhone 16 Launch
A18: A140 | B18: Instagram | C18: 45488 | D18: Tweet | E18: #AppleMusic, #AppleLifestyle | F18: 14891 | G18: 674 | H18: 521 | I18: 1091 | J18: 18101 | K18: 53669 | L18: 0.2997261 | M18: Apple Watch Ultra 2 Launch
A19: A83 | B19: Instagram | C19: 45580 | D19: Carousel | E19: #ShotOniPhone | F19: 17781 | G19: 993 | H19: 627 | I19: 2187 | J19: 9609 | K19: 66155 | L19: 0.29326582 | M19: iPhone 16 Launch
A20: A196 | B20: Twitter | C20: 45918 | D20: Tweet | E20: #MacBookProM3 | F20: 10152 | G20: 1445 | H20: 526 | I20: 513 | J20: 18959 | K20: 43712 | L20: 0.27733803 | M20: Apple Event September 2025
A21: A136 | B21: Instagram | C21: 45932 | D21: Carousel | E21: #AppleDesign, #Innovation | F21: 12161 | G21: 736 | H21: 876 | I21: 1233 | J21: 21337 | K21: 50225 | L21: 0.27422598 | M21: Apple Event September 2025
A22: A5 | B22: YouTube | C22: 45904 | D22: Video | E22: #AppleWatchUltra2, #HealthTech | F22: 21708 | G22: 435 | H22: 317 | I22: 1213 | J22: 70701 | K22: 83585 | L22: 0.2687085 | M22: Apple Event September 2025
A23: A80 | B23: LinkedIn | C23: 45456 | D23: Image | E23: #AppleWatchUltra2, #HealthTech | F23: 14173 | G23: 294 | H23: 257 | I23: 1288 | J23: 39466 | K23: 55563 | L23: 0.26499649 | M23: MacBook Air M3 Campaign
... A301: A167 | B301: LinkedIn | C301: 45624 | D301: Carousel | E301: #AppleEvent, #iPhone16 | F301: 2302 | G301: 347 | H301: 642 | I301: 2175 | J301: 56378 | K301: 198056 | L301: 0.016616513 | M301: MacBook Air M3 Campaign

Sheet Task1_Cleaned_Engagement
A1: Week_Start_Date | B1: Platform | C1: New_Followers | D1: Unfollows | E1: Total_Followers | F1: Engagement_Rate_100 | G1: Engagement_Rate | H1: NewFollower-Unfollower | I1: Follower_Growth_Rate | J1: Campaign | K1: Ad_Spend
A2: 45446 | B2: Instagram | C2: 4138 | D2: 361 | E2: 103777 | F2: 56.637791 | G2: =F2/100 -> 0.56637791 | H2: 3777 | I2: 0.036395348 | J2: {=IFERROR(INDEX(Cleaned_Campaign_Metadata!A$2:A$6,MATCH(1,(A2 >= Cleaned_Campaign_Metadata!B$2:B$6) *(A2 <= Cleaned_Campaign_Metadata!C$2:C$6),0)),"")} | K2: 23944
A3: 45446 | B3: Twitter | C3: 8693 | D3: 1261 | E3: 111209 | F3: 69.475492 | G3: =F3/100 -> 0.69475492 | H3: 7432 | I3: 0.066829124 | J3: {=IFERROR(INDEX(Cleaned_Campaign_Metadata!A$2:A$6,MATCH(1,(A3 >= Cleaned_Campaign_Metadata!B$2:B$6) *(A3 <= Cleaned_Campaign_Metadata!C$2:C$6),0)),"")} | K3: 29873
A4: 45446 | B4: YouTube | C4: 9264 | D4: 1141 | E4: 119332 | F4: 92.312205 | G4: =F4/100 -> 0.92312205 | H4: 8123 | I4: 0.068070593 | J4: {=IFERROR(INDEX(Cleaned_Campaign_Metadata!A$2:A$6,MATCH(1,(A4 >= Cleaned_Campaign_Metadata!B$2:B$6) *(A4 <= Cleaned_Campaign_Metadata!C$2:C$6),0)),"")} | K4: 50372 | L4: Power query is used in the engagement dataset which is cleaned
A5: 45446 | B5: YouTube | C5: 8842 | D5: 971 | E5: 127203 | F5: 16.351816 | G5: =F5/100 -> 0.16351816 | H5: 7871 | I5: 0.061877471 | J5: {=IFERROR(INDEX(Cleaned_Campaign_Metadata!A$2:A$6,MATCH(1,(A5 >= Cleaned_Campaign_Metadata!B$2:B$6) *(A5 <= Cleaned_Campaign_Metadata!C$2:C$6),0)),"")} | K5: 33928 | L5: Also, I have formatted datas. Date format is done. New follower,Unfollows,etc are in number format with comma(,).
A6: 45453 | B6: Instagram | C6: 7721 | D6: 506 | E6: 134418 | F6: 35.577824 | G6: =F6/100 -> 0.35577824 | H6: 7215 | I6: 0.053675847 | J6: {=IFERROR(INDEX(Cleaned_Campaign_Metadata!A$2:A$6,MATCH(1,(A6 >= Cleaned_Campaign_Metadata!B$2:B$6) *(A6 <= Cleaned_Campaign_Metadata!C$2:C$6),0)),"")} | K6: 25379
A7: 45453 | B7: Twitter | C7: 5225 | D7: 291 | E7: 146830 | F7: 19.551863 | G7: =F7/100 -> 0.19551863 | H7: 4934 | I7: 0.033603487 | J7: {=IFERROR(INDEX(Cleaned_Campaign_Metadata!A$2:A$6,MATCH(1,(A7 >= Cleaned_Campaign_Metadata!B$2:B$6) *(A7 <= Cleaned_Campaign_Metadata!C$2:C$6),0)),"")} | K7: 44546
A8: 45453 | B8: Twitter | C8: 3978 | D8: 543 | E8: 150265 | F8: 49.159818 | G8: =F8/100 -> 0.49159818 | H8: 3435 | I8: 0.022859615 | J8: {=IFERROR(INDEX(Cleaned_Campaign_Metadata!A$2:A$6,MATCH(1,(A8 >= Cleaned_Campaign_Metadata!B$2:B$6) *(A8 <= Cleaned_Campaign_Metadata!C$2:C$6),0)),"")} | K8: 34286
A9: 45453 | B9: YouTube | C9: 8002 | D9: 524 | E9: 141896 | F9: 52.064893 | G9: =F9/100 -> 0.52064893 | H9: 7478 | I9: 0.052700569 | J9: {=IFERROR(INDEX(Cleaned_Campaign_Metadata!A$2:A$6,MATCH(1,(A9 >= Cleaned_Campaign_Metadata!B$2:B$6) *(A9 <= Cleaned_Campaign_Metadata!C$2:C$6),0)),"")} | K9: 46751
A10: 45460 | B10: Instagram | C10: 8373 | D10: 921 | E10: 157717 | F10: 12.226329 | G10: =F10/100 -> 0.12226329 | H10: 7452 | I10: 0.047249187 | J10: {=IFERROR(INDEX(Cleaned_Campaign_Metadata!A$2:A$6,MATCH(1,(A10 >= Cleaned_Campaign_Metadata!B$2:B$6) *(A10 <= Cleaned_Campaign_Metadata!C$2:C$6),0)),"")} -> iPhone 16 Launch | K10: 15110
A11: 45460 | B11: Instagram | C11: 6656 | D11: 978 | E11: 176196 | F11: 60.425889 | G11: =F11/100 -> 0.60425889 | H11: 5678 | I11: 0.032225476 | J11: {=IFERROR(INDEX(Cleaned_Campaign_Metadata!A$2:A$6,MATCH(1,(A11 >= Cleaned_Campaign_Metadata!B$2:B$6) *(A11 <= Cleaned_Campaign_Metadata!C$2:C$6),0)),"")} -> iPhone 16 Launch | K11: 27081
A12: 45460 | B12: LinkedIn | C12: 7097 | D12: 369 | E12: 170518 | F12: 9.2506363 | G12: =F12/100 -> 0.092506363 | H12: 6728 | I12: 0.039456245 | J12: {=IFERROR(INDEX(Cleaned_Campaign_Metadata!A$2:A$6,MATCH(1,(A12 >= Cleaned_Campaign_Metadata!B$2:B$6) *(A12 <= Cleaned_Campaign_Metadata!C$2:C$6),0)),"")} -> iPhone 16 Launch | K12: 33762
A13: 45460 | B13: Twitter | C13: 6907 | D13: 834 | E13: 163790 | F13: 54.158984 | G13: =F13/100 -> 0.54158984 | H13: 6073 | I13: 0.037077966 | J13: {=IFERROR(INDEX(Cleaned_Campaign_Metadata!A$2:A$6,MATCH(1,(A13 >= Cleaned_Campaign_Metadata!B$2:B$6) *(A13 <= Cleaned_Campaign_Metadata!C$2:C$6),0)),"")} -> iPhone 16 Launch | K13: 22087
A14: 45467 | B14: Instagram | C14: 5259 | D14: 374 | E14: 189735 | F14: 14.827523 | G14: =F14/100 -> 0.14827523 | H14: 4885 | I14: 0.025746436 | J14: {=IFERROR(INDEX(Cleaned_Campaign_Metadata!A$2:A$6,MATCH(1,(A14 >= Cleaned_Campaign_Metadata!B$2:B$6) *(A14 <= Cleaned_Campaign_Metadata!C$2:C$6),0)),"")} -> iPhone 16 Launch | K14: 19596
A15: 45467 | B15: Twitter | C15: 9984 | D15: 1330 | E15: 184850 | F15: 57.524479 | G15: =F15/100 -> 0.57524479 | H15: 8654 | I15: 0.046816338 | J15: {=IFERROR(INDEX(Cleaned_Campaign_Metadata!A$2:A$6,MATCH(1,(A15 >= Cleaned_Campaign_Metadata!B$2:B$6) *(A15 <= Cleaned_Campaign_Metadata!C$2:C$6),0)),"")} -> iPhone 16 Launch | K15: 44947
A16: 45467 | B16: Twitter | C16: 6901 | D16: 471 | E16: 204818 | F16: 60.827662 | G16: =F16/100 -> 0.60827662 | H16: 6430 | I16: 0.031393725 | J16: {=IFERROR(INDEX(Cleaned_Campaign_Metadata!A$2:A$6,MATCH(1,(A16 >= Cleaned_Campaign_Metadata!B$2:B$6) *(A16 <= Cleaned_Campaign_Metadata!C$2:C$6),0)),"")} -> iPhone 16 Launch | K16: 52003
A17: 45467 | B17: YouTube | C17: 9286 | D17: 633 | E17: 198388 | F17: 5.4343005 | G17: =F17/100 -> 0.054343005 | H17: 8653 | I17: 0.043616549 | J17: {=IFERROR(INDEX(Cleaned_Campaign_Metadata!A$2:A$6,MATCH(1,(A17 >= Cleaned_Campaign_Metadata!B$2:B$6) *(A17 <= Cleaned_Campaign_Metadata!C$2:C$6),0)),"")} -> iPhone 16 Launch | K17: 48019
... A201: 45789 | B201: Twitter | C201: 8527 | D201: 1091 | E201: 1186398 | F201: 1.6760817 | G201: =F201/100 -> 0.016760817 | H201: 7436 | I201: 0.0062677112 | J201: {=IFERROR(INDEX(Cleaned_Campaign_Metadata!A$2:A$6,MATCH(1,(A201 >= Cleaned_Campaign_Metadata!B$2:B$6) *(A201 <= Cleaned_Campaign_Metadata!C$2:C$6),0)),"")} | K201: 41703

Sheet Task1_Cleaned_Campaign
A1: Campaign_Name | B1: Start_Date | C1: End_Date | D1: Objective | E1: Ad_Spend | F1: Impressions | G1: Engagement_Uplift
A2: iPhone 16 Launch | B2: 45458 | C2: 45488 | D2: Product Launch | E2: 85000 | F2: 950000 | G2: 0.45
A3: MacBook Air M3 Campaign | B3: 45566 | C3: 45596 | D3: Product Promotion | E3: 60000 | F3: 780000 | G3: 0.38
A4: Apple Watch Ultra 2 Launch | B4: 45651 | C4: 45667 | D4: Health & Fitness Awareness | E4: 55000 | F4: 700000 | G4: 0.41
A5: Sustainability Awareness Drive | B5: 45717 | C5: 45747 | D5: Sustainability Branding | E5: 40000 | F5: 550000 | G5: 0.32
A6: Apple Event September 2025 | B6: 45901 | C6: 45930 | D6: Brand Engagement | E6: 75000 | F6: 880000 | G6: 0.47
A8: Power query is used in the engagement dataset which is cleaned
A9: Date format is done. Ad spend,Impressions etc are in number format with comma(,).

Sheet Task-2
A1: Using the Posts Dataset:
A2: ● Calculate average engagement rate per platform:
A3: Engagement Rate = (Likes + Shares + Comments) / Impressions
A4: ● Identify Top 10 Apple posts with highest engagement.
A5: ● Create a pivot table showing:
A6: ○ Total Likes, Shares, Comments by Content Type & Platform
A7: ○ Average Clicks per post by Hashtag
A8: ● Highlight top-performing hashtags such as #ShotOniPhone, #AppleEvent, #iPhone16Launch, #MacBookAir.
A14: ● Calculate average engagement rate per platform:
A15: Platform | B15: Average of EngagementRate
A16: Instagram | B16: 0.11777136 | C16: Pivot table is used, Engagement rate is calculated with the given formula and converted into % percentage format
A17: LinkedIn | B17: 0.12413747 | C17: Twitter has higher engagement rate among all platforms
A18: Twitter | B18: 0.13887773
A19: YouTube | B19: 0.11218828
A20: Grand Total | B20: 0.12284133
A25: ● Identify Top 10 Apple posts with highest engagement.
A26: PostID | B26: Platform | C26: EngagementRate
A27: A82 | B27: LinkedIn | C27: 0.49054106
A28: A201 | B28: YouTube | C28: 0.48803915 | E28: Sorting is used based on the Engagement rate. Copied the postID for the top 10 platform
A29: A121 | B29: LinkedIn | C29: 0.45492807 | E29: The top 10 post IDs are A82, A201, A121, A127, A13, A123, A287, A226, A231, and A185.
A30: A127 | B30: Twitter | C30: 0.41655672
A31: A13 | B31: YouTube | C31: 0.40382152
A32: A123 | B32: Twitter | C32: 0.39401344
A33: A287 | B33: Instagram | C33: 0.367641
A34: A226 | B34: Twitter | C34: 0.35412345
A35: A231 | B35: Twitter | C35: 0.33944448
A36: A185 | B36: Instagram | C36: 0.33811899
A39: ○ Total Likes, Shares, Comments by Content Type & Platform | F39: Pivot table, Conditional Formatting method is used
A40: Row Labels | B40: Sum of Likes | C40: Sum of Shares | D40: Sum of Comments | F40: LinkedIn has highest number of likes, shares, comments
A41: Instagram | B41: 947196 | C41: 63205 | D41: 40786
A42: Carousel | B42: 278757 | C42: 16508 | D42: 13676
A43: Image | B43: 218031 | C43: 18753 | D43: 10389
A44: Tweet | B44: 206053 | C44: 14750 | D44: 9295
A45: Video | B45: 244355 | C45: 13194 | D45: 7426
A46: LinkedIn | B46: 1134366 | C46: 70960 | D46: 49700
A47: Carousel | B47: 246297 | C47: 18856 | D47: 12611
A48: Image | B48: 329722 | C48: 19905 | D48: 14305
A49: Tweet | B49: 279588 | C49: 17963 | D49: 11014
A50: Video | B50: 278759 | C50: 14236 | D50: 11770
A51: Twitter | B51: 1037623 | C51: 59661 | D51: 39273
...

Sheet Task-2.2-Top_10_Posts
A1: PostID | B1: Platform | C1: EngagementRate
A2: A82 | B2: LinkedIn | C2: 0.49054106
A3: A201 | B3: YouTube | C3: 0.48803915
A4: A121 | B4: LinkedIn | C4: 0.45492807
A5: A127 | B5: Twitter | C5: 0.41655672
A6: A13 | B6: YouTube | C6: 0.40382152
A7: A123 | B7: Twitter | C7: 0.39401344
A8: A287 | B8: Instagram | C8: 0.367641
A9: A226 | B9: Twitter | C9: 0.35412345
A10: A231 | B10: Twitter | C10: 0.33944448
A11: A185 | B11: Instagram | C11: 0.33811899

Sheet Sheet7
B3: Column Labels
B4: Carousel | E4: Image | H4: Tweet | K4: Video | N4: (blank) | Q4: Total Sum of Likes | R4: Total Sum of Shares | S4: Total Sum of Comments
A5: Row Labels | B5: Sum of Likes | C5: Sum of Shares | D5: Sum of Comments | E5: Sum of Likes | F5: Sum of Shares | G5: Sum of Comments | H5: Sum of Likes | I5: Sum of Shares | J5: Sum of Comments | K5: Sum of Likes | L5: Sum of Shares | M5: Sum of Comments | N5: Sum of Likes | O5: Sum of Shares | P5: Sum of Comments
A6: Instagram | B6: 278757 | C6: 16508 | D6: 13676 | E6: 218031 | F6: 18753 | G6: 10389 | H6: 206053 | I6: 14750 | J6: 9295 | K6: 244355 | L6: 13194 | M6: 7426 | Q6: 947196 | R6: 63205 | S6: 40786
A7: LinkedIn | B7: 246297 | C7: 18856 | D7: 12611 | E7: 329722 | F7: 19905 | G7: 14305 | H7: 279588 | I7: 17963 | J7: 11014 | K7: 278759 | L7: 14236 | M7: 11770 | Q7: 1134366 | R7: 70960 | S7: 49700
A8: Twitter | B8: 394886 | C8: 21298 | D8: 14381 | E8: 148676 | F8: 7832 | G8: 6092 | H8: 249305 | I8: 15862 | J8: 9160 | K8: 244756 | L8: 14669 | M8: 9640 | Q8: 1037623 | R8: 59661 | S8: 39273
A9: YouTube | B9: 279732 | C9: 24668 | D9: 13714 | E9: 195079 | F9: 10604 | G9: 8277 | H9: 187129 | I9: 14136 | J9: 8101 | K9: 286318 | L9: 18052 | M9: 12537 | Q9: 948258 | R9: 67460 | S9: 42629
A10: (blank)
A11: Grand Total | B11: 1199672 | C11: 81330 | D11: 54382 | E11: 891508 | F11: 57094 | G11: 39063 | H11: 922075 | I11: 62711 | J11: 37570 | K11: 1054188 | L11: 60151 | M11: 41373 | Q11: 4067443 | R11: 261286 | S11: 172388

Sheet Sheet9
A3: Hashtags | B3: Average of Clicks
A4: #iPhone16Launch, #AppleEvent | B4: 1811.3103
A5: #AppleWatch, #Health | B5: 1711.5135
A6: #iPhonePhotography, #ShotOniPhone | B6: 1706.76
A7: #MacBookAirM3, #AppleInnovation | B7: 1680.3571
A8: #AppleWatchUltra2, #HealthTech | B8: 1674.96
A9: #ShotOniPhone | B9: 1592.9375
A10: #AppleDesign, #Innovation | B10: 1592.72
A11: #AppleEvent, #iPhone16 | B11: 1579.4375
A12: #AppleEvent, #iPadPro | B12: 1477.2632
A13: #AppleMusic, #AppleLifestyle | B13: 1463.2941
A14: #Sustainability, #AppleEarth | B14: 1459.3077
A15: #MacBookProM3 | B15: 1289.4118
A16: (blank)
A17: Grand Total | B17: 1606.6833

Sheet Task-3
A1: Identify the platform with highest engagement (e.g., Twitter for announcements vs. YouTube for product demos).
A4: Average of EngagementRate | B4: Column Labels
A5: Row Labels | B5: Twitter | C5: LinkedIn | D5: Instagram | E5: YouTube
A6: Apple Event September 2025 | B6: 0.14856462 | C6: 0.11210848 | D6: 0.13193785 | E6: 0.10380076
A7: Apple Watch Ultra 2 Launch | B7: 0.1430731 | C7: 0.1441191 | D7: 0.13679934 | E7: 0.11973748
A8: iPhone 16 Launch | B8: 0.1352676 | C8: 0.12843165 | D8: 0.096402731 | E8: 0.11995588
A9: MacBook Air M3 Campaign | B9: 0.14429365 | C9: 0.12478605 | D9: 0.09560217 | E9: 0.11559353
A10: Sustainability Awareness Drive | B10: 0.12718694 | C10: 0.1020845 | D10: 0.11414924 | E10: 0.10497763
A12: Twitter has the highest engagement rate across all campaigns mostly.
A14: Pivot table, Conditional Formatting, pivot chart is used.
A26: Compare Follower Growth Rates Across Platforms
A28: Platform | B28: Average of Follower_Growth_Rate
A29: YouTube | B29: 0.014194034
A30: Twitter | B30: 0.013764362
A31: Instagram | B31: 0.012030686
A32: LinkedIn | B32: 0.0094286448
A33: Grand Total | B33: 0.012218035
A36: YouTube has the highest follower growth rate at 1.42%, followed by Twitter (1.38%), Instagram (1.20%), and LinkedIn (0.94%).
A38: Pivot table, Conditional Formatting, pivot chart is used.

Sheet Task-3-Continue
A1: Platform | B1: Engagement_Rate | C1: Ad_Spend
A2: Instagram | B2: 56.637791 | C2: 23944 | H2: Visualize Engagement vs. Ad Spend per platform.
A3: Instagram | B3: 35.577824 | C3: 25379
A4: Instagram | B4: 12.226329 | C4: 15110 | H4: Pivot table, Conditional Formatting, Scatter plot chart is used.
A5: Instagram | B5: 60.425889 | C5: 27081 | H5: The scatter plot is what actually visualizes the relationship between Engagement Rate and Ad Spend.
A6: Instagram | B6: 14.827523 | C6: 19596 | H6: This suggests that YouTube and Twitter deliver better engagement efficiency compared to other platforms.
A7: Instagram | B7: 12.83722 | C7: 11013
A8: Instagram | B8: 17.412787 | C8: 59378
A9: Instagram | B9: 13.63559 | C9: 23109
A10: Instagram | B10: 12.157626 | C10: 36661
A11: Instagram | B11: 27.765519 | C11: 39197
A12: Instagram | B12: 44.450416 | C12: 39750
A13: Instagram | B13: 13.477303 | C13: 46727
A14: Instagram | B14: 5.769462 | C14: 53543
A15: Instagram | B15: 3.6633502 | C15: 24226
A16: Instagram | B16: 30.118587 | C16: 53922
A17: Instagram | B17: 33.909843 | C17: 54848
A18: Instagram | B18: 33.257448 | C18: 22693
... A36: Instagram | B36: 1.3811779 | C36: 17999
A37: Instagram | B37: 15.062313 | C37: 58201 | F37: Advise Apple’s team: Should they focus on YouTube + Instagram (videos + visuals) or continue a multi-platform strategy?
A38: Instagram | B38: 13.941172 | C38: 15105
A39: Instagram | B39: 11.12441 | C39: 47051 | F39: Yes, Apple should focus more on Instagram and YouTube, as both show strong engagement and good ROI.
A40: Instagram | B40: 14.789894 | C40: 37037
A41: Instagram | B41: 2.3800169 | C41: 19557 | F41: However, they should not ignore LinkedIn and Twitter, since these platforms still maintain high engagement levels across campaigns.
A42: Instagram | B42: 3.4123326 | C42: 19435
A43: Instagram | B43: 7.4744447 | C43: 44742 | F43: A balanced multi-platform approach will help maximize reach while leveraging YouTube and Instagram’s visual and video strengths.
A44: Instagram | B44: 3.8694093 | C44: 44782
A45: Instagram | B45: 12.455175 | C45: 59733
A46: Instagram | B46: 5.5892257 | C46: 48328
A47: Instagram | B47: 12.709773 | C47: 42262
A48: Instagram | B48: 12.414412 | C48: 58330
A49: Instagram | B49: 2.2102165 | C49: 11171
A50: Instagram | B50: 10.234893 | C50: 51903
A51: Instagram | B51: 3.8777032 | C51: 30644
A52: Instagram | B52: 7.2439222 | C52: 28745
A53: LinkedIn | B53: 9.2506363 | C53: 33762
A54: LinkedIn | B54: 17.894036 | C54: 28313
A55: LinkedIn | B55: 39.284614 | C55: 11828
... A201: YouTube | B201: 6.9871371 | C201: 32669

Sheet Task-4
A1: Identify the most frequently used Apple hashtags | E1: Compare average performance of posts containing each hashtag.
A3: Row Labels | B3: Count of Hashtags | E3: Row Labels | F3: Average of EngagementRate
A4: #AppleDesign, #Innovation | B4: 25 | E4: #AppleDesign, #Innovation | F4: 0.11135741
A5: #AppleEvent, #iPadPro | B5: 19 | E5: #AppleEvent, #iPadPro | F5: 0.11195695
A6: #AppleEvent, #iPhone16 | B6: 32 | E6: #AppleEvent, #iPhone16 | F6: 0.12600407 | H6: Pivot table, Conditional Formatting is used
A7: #AppleMusic, #AppleLifestyle | B7: 34 | E7: #AppleMusic, #AppleLifestyle | F7: 0.13494947
A8: #AppleWatch, #Health | B8: 37 | E8: #AppleWatch, #Health | F8: 0.11399722 | H8: #ShotOniPhone has the highest engagement with 15.33%
A9: #AppleWatchUltra2, #HealthTech | B9: 25 | E9: #AppleWatchUltra2, #HealthTech | F9: 0.14380411
A10: #iPhone16Launch, #AppleEvent | B10: 29 | E10: #iPhone16Launch, #AppleEvent | F10: 0.1145658
A11: #iPhonePhotography, #ShotOniPhone | B11: 25 | E11: #iPhonePhotography, #ShotOniPhone | F11: 0.12026677
A12: #MacBookAirM3, #AppleInnovation | B12: 28 | E12: #MacBookAirM3, #AppleInnovation | F12: 0.1178941
A13: #MacBookProM3 | B13: 17 | E13: #MacBookProM3 | F13: 0.10955527
A14: #ShotOniPhone | B14: 16 | E14: #ShotOniPhone | F14: 0.15329917
A15: #Sustainability, #AppleEarth | B15: 13 | E15: #Sustainability, #AppleEarth | F15: 0.12019462
E16: Grand Total | F16: 0.12284133
A17: Pivot table, Conditional Formatting is used
A19: #AppleWatch, #Health hashtag is the most frequently used one with count 37

Sheet Detail1
A1: Details for Sum of Likes - Platform: LinkedIn, ContentType: Tweet
A3: PostID | B3: Platform | C3: Date | D3: ContentType | E3: Hashtags | F3: Likes | G3: Shares | H3: Comments | I3: Clicks | J3: Reach | K3: Impressions | L3: EngagementRate | M3: Campaign
A4: A69 | B4: LinkedIn | C4: 45724 | D4: Tweet | E4: #AppleWatch, #Health | F4: 10580 | G4: 427 | H4: 790 | I4: 2814 | J4: 24916 | K4: 213312 | L4: 0.055303968 | M4: MacBook Air M3 Campaign
A5: A15 | B5: LinkedIn | C5: 45907 | D5: Tweet | E5: #AppleDesign, #Innovation | F5: 3015 | G5: 997 | H5: 783 | I5: 617 | J5: 77167 | K5: 82229 | L5: 0.058312761 | M5: Apple Event September 2025
A6: A111 | B6: LinkedIn | C6: 45619 | D6: Tweet | E6: #ShotOniPhone | F6: 9941 | G6: 1329 | H6: 238 | I6: 869 | J6: 40281 | K6: 172311 | L6: 0.066786218 | M6: Sustainability Awareness Drive
A7: A45 | B7: LinkedIn | C7: 45917 | D7: Tweet | E7: #AppleMusic, #AppleLifestyle | F7: 15456 | G7: 590 | H7: 555 | I7: 2882 | J7: 49816 | K7: 240422 | L7: 0.069049421 | M7: Apple Event September 2025
A8: A17 | B8: LinkedIn | C8: 45782 | D8: Tweet | E8: #AppleEvent, #iPhone16 | F8: 10415 | G8: 1388 | H8: 725 | I8: 2462 | J8: 53082 | K8: 168267 | L8: 0.074453101 | M8: MacBook Air M3 Campaign
A9: A175 | B9: LinkedIn | C9: 45938 | D9: Tweet | E9: #AppleEvent, #iPhone16 | F9: 17745 | G9: 414 | H9: 563 | I9: 2733 | J9: 995 | K9: 231648 | L9: 0.080820901 | M9: Apple Event September 2025
A10: A56 | B10: LinkedIn | C10: 45644 | D10: Tweet | E10: #iPhone16Launch, #AppleEvent | F10: 14775 | G10: 1220 | H10: 640 | I10: 1547 | J10: 28527 | K10: 183660 | L10: 0.090574975 | M10: MacBook Air M3 Campaign
A11: A208 | B11: LinkedIn | C11: 45467 | D11: Tweet | E11: #MacBookAirM3, #AppleInnovation | F11: 5596 | G11: 1231 | H11: 473 | I11: 2251 | J11: 43705 | K11: 75643 | L11: 0.096505956 | M11: Apple Watch Ultra 2 Launch
A12: A243 | B12: LinkedIn | C12: 45722 | D12: Tweet | E12: #iPhone16Launch, #AppleEvent | F12: 22119 | G12: 899 | H12: 642 | I12: 410 | J12: 49490 | K12: 229420 | L12: 0.10312963 | M12: iPhone 16 Launch
A13: A272 | B13: LinkedIn | C13: 45743 | D13: Tweet | E13: #iPhonePhotography, #ShotOniPhone | F13: 14819 | G13: 1432 | H13: 152 | I13: 961 | J13: 39154 | K13: 154793 | L13: 0.10596732 | M13: iPhone 16 Launch
A14: A235 | B14: LinkedIn | C14: 45648 | D14: Tweet | E14: #AppleEvent, #iPadPro | F14: 20117 | G14: 1143 | H14: 713 | I14: 1739 | J14: 34444 | K14: 198670 | L14: 0.11060049 | M14: MacBook Air M3 Campaign
A15: A19 | B15: LinkedIn | C15: 45466 | D15: Tweet | E15: #AppleEvent, #iPhone16 | F15: 16512 | G15: 1050 | H15: 971 | I15: 1891 | J15: 15865 | K15: 166503 | L15: 0.1113073 | M15: iPhone 16 Launch
... A22: A46 | B22: LinkedIn | C22: 45779 | D22: Tweet | E22: #AppleEvent, #iPhone16 | F22: 17444 | G22: 1402 | H22: 218 | I22: 725 | J22: 8710 | K22: 85893 | L22: 0.22195057 | M22: MacBook Air M3 Campaign

Sheet Task-4-Continue..
A1: Compare content performance:
A2: Videos (launch events, ads, product demos)
A3: Images (product close-ups, lifestyle shots)
A4: Carousels (feature highlights, comparisons)
A6: Average of EngagementRate | B6: Column Labels
A7: Row Labels | B7: Apple Event September 2025 | C7: Apple Watch Ultra 2 Launch | D7: iPhone 16 Launch | E7: MacBook Air M3 Campaign | F7: Sustainability Awareness Drive | G7: Grand Total | H7: Pivot table, Conditional Formatting is used
A8: Carousel | B8: 0.10659328 | C8: 0.14428992 | D8: 0.13296104 | E8: 0.13817872 | F8: 0.087845983 | G8: 0.12254707
A9: Image | B9: 0.1299258 | C9: 0.11270937 | D9: 0.11354346 | E9: 0.11576725 | F9: 0.099531955 | G9: 0.11546429
A10: Tweet | B10: 0.11931131 | C10: 0.1199968 | D10: 0.11429578 | E10: 0.10776982 | F10: 0.10373784 | G10: 0.11357605 | H10: Videos achieved the highest average engagement rate (13.93%), followed by carousels (12.25%) and images (11.55%).
A11: Video | B11: 0.13265746 | C11: 0.16660506 | D11: 0.12164066 | E11: 0.098301267 | F11: 0.14671342 | G11: 0.13929223 | H11: While tweets performed the lowest at 11.36%, indicating that video content drives the most audience interaction.
A12: Grand Total | B12: 0.12042553 | C12: 0.1368382 | D12: 0.12196385 | E12: 0.11861255 | F12: 0.11314309 | G12: 0.12284133
A15: Recommend which content type performs best on each platform(e.g., videos for YouTube, product images for Instagram).
C16: Row Labels | D16: Sum of Likes
C17: Carousel | D17: 1199672
C18: Instagram | D18: 278757 | E18: Pivot table is used
C19: LinkedIn | D19: 246297
C20: Twitter | D20: 394886
C21: YouTube | D21: 279732 | E21: My Recommendation:
C22: Image | D22: 891508 | E22: Carousel for Twitter
C23: Instagram | D23: 218031 | E23: Image for LinkedIn
C24: LinkedIn | D24: 329722 | E24: Tweet for LinkedIn
C25: Twitter | D25: 148676 | E25: Video for YouTube
C26: YouTube | D26: 195079
C27: Tweet | D27: 922075
C28: Instagram | D28: 206053
C29: LinkedIn | D29: 279588
C30: Twitter | D30: 249305
C31: YouTube | D31: 187129
C32: Video | D32: 1054188
C33: Instagram | D33: 244355
C34: LinkedIn | D34: 278759
C35: Twitter | D35: 244756
C36: YouTube | D36: 286318

Sheet Task 5.1
A5: Total & Average Impressions,Likes,Clicks per Campaign
A10: Campaign | B10: Sum of Clicks | C10: Average of Clicks | D10: Sum of Impressions | E10: Average of Impressions | F10: Sum of Likes | G10: Average of Likes
A11: Apple Event September 2025 | B11: 114854 | C11: 1664.5507 | D11: 10331022 | E11: 149724.96 | F11: 957050 | G11: 13870.29
A12: Apple Watch Ultra 2 Launch | B12: 106775 | C12: 1547.4638 | D12: 9407749 | E12: 136344.19 | F12: 888529 | G12: 12877.232
A13: iPhone 16 Launch | B13: 96543 | C13: 1636.322 | D13: 8901334 | E13: 150870.07 | F13: 843431 | G13: 14295.441
A14: MacBook Air M3 Campaign | B14: 74667 | C14: 1623.1957 | D14: 6698763 | E14: 145625.28 | F14: 585970 | G14: 12738.478
A15: Sustainability Awareness Drive | B15: 89166 | C15: 1564.3158 | D15: 9222999 | E15: 161807 | F15: 792463 | G15: 13902.86
A17: Pivot table, Conditional Formatting is used.
A18: Highlighted top 1% with conditional formatting cell-Sum with yellow and Average with Red

Sheet Task 5.2
A2: Measure engagement uplift during vs. before campaigns (e.g., iPhone 16 launch spike).
A8: Campaign_Name | B8: Start_Date | C8: End_Date | D8: Engagement_During | E8: Engagement_Before
A9: iPhone 16 Launch | B9: 45458 | C9: 45488 | D9: {=AVERAGEIFS(Cleaned_Posts_Dataset!L:L,Cleaned_Posts_Dataset!C:C,">=" &'Task 5.2'!$B$9:$B$13,Cleaned_Posts_Dataset!C:C, "<=" &'Task 5.2'!$C$9:$C$13)} -> 0.11793 | E9: {=AVERAGEIFS(Cleaned_Posts_Dataset!L:L,Cleaned_Posts_Dataset!C:C,">=" &('Task 5.2'!$B$9:$B$13-180),Cleaned_Posts_Dataset!C:C, "<" &'Task 5.2'!$B$9:$B$13)} -> 0.15408513 | G9: AVERAGEIFS,Table copy paste is used.
A10: MacBook Air M3 Campaign | B10: 45566 | C10: 45596 | D10: 0.1117943 | E10: 0.13125333 | G10: Engagement uplift analysis shows that while most campaigns saw a slight drop in engagement during their active periods.
A11: Apple Watch Ultra 2 Launch | B11: 45651 | C11: 45667 | D11: 0.070774062 | E11: 0.1246346 | G11: The Apple Event September 2025 achieved a uplift, increasing from 10.02% before to 12.63% during the campaign.
A12: Sustainability Awareness Drive | B12: 45717 | C12: 45747 | D12: 0.10860491 | E12: 0.12490666
A13: Apple Event September 2025 | B13: 45901 | C13: 45930 | D13: 0.12625459 | E13: 0.1001737

Sheet Task-5-Insights
A1: Insights:
A2: ○ Which campaign had the highest ROI (engagement vs. spend)?
A3: ○ Which campaign drove the strongest follower growth?
A6: Row Labels | B6: Average of Engagement_Rate | C6: Average of Ad_Spend
A7: Apple Watch Ultra 2 Launch | B7: 0.089415431 | C7: 40359.125
A8: iPhone 16 Launch | B8: 0.26316567 | C8: 31353.8
A9: MacBook Air M3 Campaign | B9: 0.12694932 | C9: 36221.5
A10: Sustainability Awareness Drive | B10: 0.062842734 | C10: 35630.1
A11: Grand Total | B11: 0.14479189 | C11: 35032.734
A14: Pivot table, Conditional Formatting is used. Combo chart is mentioned.
A15: The iPhone 16 Launch campaign delivered the best ROI, achieving the highest engagement rate (26.32%) relative to its ad spend.
A24: Which campaign drove the strongest follower growth?
A26: Row Labels | B26: Average of Follower_Growth_Rate
A27: Apple Watch Ultra 2 Launch | B27: 0.0081853409
A28: iPhone 16 Launch | B28: 0.026400203
A29: MacBook Air M3 Campaign | B29: 0.011432169
A30: Sustainability Awareness Drive | B30: 0.0052818011
A31: Grand Total | B31: 0.013781836
A34: Pivot table and bar chart is used.
A35: The iPhone 16 Launch also drove the strongest follower growth at 2.64%

Sheet Task-6.1
A1: Visualize Weekly Follower Growth per Platform(Line chart)
A2: Pivot table, Conditional Formatting is used with TOP 1%. Line chart with marker is used.
H3: Identify the Peak Week of Follower Gain
H4: The week starting July 22, 2024, recorded the highest total follower gain across all platforms.
H6: Sum of New_Followers | I6: Column Labels
H7: Row Labels | I7: Instagram | J7: LinkedIn | K7: Twitter | L7: YouTube | M7: Grand Total
H8: 45446 | I8: 4138 | K8: 8693 | L8: 18106 | M8: 30937
H9: 45453 | I9: 7721 | K9: 9203 | L9: 8002 | M9: 24926
H10: 45460 | I10: 15029 | J10: 7097 | K10: 6907 | M10: 29033
H11: 45467 | I11: 5259 | K11: 16885 | L11: 9286 | M11: 31430
H12: 45474 | I12: 6490 | J12: 5917 | K12: 9429 | M12: 21836
H13: 45481 | J13: 12349 | K13: 8045 | M13: 20394
H14: 45488 | I14: 5500 | K14: 8137 | L14: 1963 | M14: 15600
H15: 45495 | J15: 17307 | K15: 8179 | L15: 9734 | M15: 35220
H16: 45502 | J16: 8622 | K16: 6947 | L16: 4036 | M16: 19605
H17: 45509 | I17: 3494 | J17: 5349 | K17: 3719 | L17: 2884 | M17: 15446
H18: 45516 | I18: 7610 | K18: 14333 | L18: 7430 | M18: 29373
H19: 45523 | I19: 15013 | L19: 10587 | M19: 25600
H20: 45530 | I20: 9648 | J20: 1689 | K20: 6175 | L20: 6078 | M20: 23590
H21: 45537 | I21: 8627 | J21: 9591 | K21: 7406 | M21: 25624
H22: 45544 | I22: 7907 | J22: 6671 | L22: 12438 | M22: 27016
H23: 45551 | J23: 2382 | K23: 4292 | L23: 10331 | M23: 17005
H24: 45558 | I24: 14578 | K24: 5517 | M24: 20095
H25: 45565 | I25: 10637 | K25: 9737 | M25: 20374
H26: 45572 | I26: 5481 | J26: 2549 | L26: 11856 | M26: 19886
H27: 45579 | K27: 18028 | L27: 7548 | M27: 25576
H28: 45586 | I28: 26389 | L28: 7793 | M28: 34182
H29: 45593 | J29: 16789 | L29: 13549 | M29: 30338
H30: 45600 | J30: 5268 | K30: 10051 | L30: 3385 | M30: 18704
H31: 45607 | J31: 5592 | K31: 10819 | L31: 5795 | M31: 22206
H32: 45614 | I32: 5798 | J32: 10242 | K32: 7036 | M32: 23076
H33: 45621 | I33: 15788 | J33: 9737 | L33: 5719 | M33: 31244
H34: 45628 | I34: 9987 | J34: 5839 | L34: 4493 | M34: 20319
H35: 45635 | I35: 3672 | J35: 1016 | K35: 7164 | L35: 5200 | M35: 17052
H36: 45642 | I36: 5583 | J36: 9616 | K36: 7272 | M36: 22471
H37: 45649 | I37: 4631 | J37: 8743 | L37: 8177 | M37: 21551
H38: 45656 | I38: 4897 | J38: 18556 | K38: 3279 | M38: 26732
H39: 45663 | J39: 9980 | K39: 10226 | L39: 9906 | M39: 30112
H40: 45670 | I40: 3247 | J40: 7869 | K40: 8088 | L40: 1078 | M40: 20282
H41: 45677 | K41: 22105 | L41: 8340 | M41: 30445
...

Sheet Sheet36
A3: Row Labels | B3: Sum of NewFollower-Unfollower
A4: <03-06-2024 | B4: 0
A5: (blank) | B5: 0
A6: Jan | B6: 96295
A7: 45663 | B7: 27057
A8: 45670 | B8: 18737
A9: 45677 | B9: 27809
A10: 45684 | B10: 22692
A11: Feb | B11: 90480
A12: 45691 | B12: 28533
A13: 45698 | B13: 13642
A14: 45705 | B14: 17859
A15: 45712 | B15: 30446
A16: Mar | B16: 107259
A17: 45719 | B17: 20389
A18: 45726 | B18: 17807
A19: 45733 | B19: 28020
A20: 45740 | B20: 25416
A21: 45747 | B21: 15627
A22: Apr | B22: 85234
A23: 45754 | B23: 20720
A24: 45761 | B24: 24995
A25: 45768 | B25: 22070
A26: 45775 | B26: 17449
A27: May | B27: 34516
A28: 45782 | B28: 16129
A29: 45789 | B29: 18387
A30: Jun | B30: 104818
A31: 45446 | B31: 27203
A32: 45453 | B32: 23062
A33: 45460 | B33: 25931
A34: 45467 | B34: 28622
A35: Jul | B35: 101486
A36: 45474 | B36: 19833
A37: 45481 | B37: 18529
A38: 45488 | B38: 13885
A39: 45495 | B39: 32218
A40: 45502 | B40: 17021
A41: Aug | B41: 84848
A42: 45509 | B42: 14100
...

Sheet Task-6.2
A1: Row Labels | B1: Sum of NewFollower-Unfollower | C1: Forecast(Sum of NewFollower-Unfollower) | D1: Lower Confidence Bound(Sum of NewFollower-Unfollower) | E1: Upper Confidence Bound(Sum of NewFollower-Unfollower)
A2: 45446 | B2: 27203 | F2: Use moving averages to smooth growth trends.
A3: 45453 | B3: 23062
A4: 45460 | B4: 25931
A5: 45467 | B5: 28622 | F5: Forecast Sheet and Pivot table method is used.
A6: 45474 | B6: 19833
A7: 45481 | B7: 18529
A8: 45488 | B8: 13885
A9: 45495 | B9: 32218
A10: 45502 | B10: 17021
A11: 45509 | B11: 14100
A12: 45516 | B12: 26686
A13: 45523 | B13: 23262
A14: 45530 | B14: 20800
A15: 45537 | B15: 22217
A16: 45544 | B16: 25176
A17: 45551 | B17: 15432
... A50: 45782 | B50: 16129
A51: 45789 | B51: 18387 | C51: 18387 | D51: 18387 | E51: 18387
A52: 45796 | C52: =_xlfn.FORECAST.ETS(A52,$B$2:$B$51,$A$2:$A$51,10,1) -> 25122.155 | D52: =C52-_xlfn.FORECAST.ETS.CONFINT(A52,$B$2:$B$51,$A$2:$A$51,0.95,10,1) -> 16153.585 | E52: =C52+_xlfn.FORECAST.ETS.CONFINT(A52,$B$2:$B$51,$A$2:$A$51,0.95,10,1) -> 34090.725
A53: 45803 | C53: =_xlfn.FORECAST.ETS(A53,$B$2:$B$51,$A$2:$A$51,10,1) -> 25112.609 | D53: =C53-_xlfn.FORECAST.ETS.CONFINT(A53,$B$2:$B$51,$A$2:$A$51,0.95,10,1) -> 16143.999 | E53: =C53+_xlfn.FORECAST.ETS.CONFINT(A53,$B$2:$B$51,$A$2:$A$51,0.95,10,1) -> 34081.22
A54: 45810 | C54: =_xlfn.FORECAST.ETS(A54,$B$2:$B$51,$A$2:$A$51,10,1) -> 19345.798 | D54: =C54-_xlfn.FORECAST.ETS.CONFINT(A54,$B$2:$B$51,$A$2:$A$51,0.95,10,1) -> 10377.116 | E54: =C54+_xlfn.FORECAST.ETS.CONFINT(A54,$B$2:$B$51,$A$2:$A$51,0.95,10,1) -> 28314.48
A55: 45817 | C55: =_xlfn.FORECAST.ETS(A55,$B$2:$B$51,$A$2:$A$51,10,1) -> 21931.867 | D55: =C55-_xlfn.FORECAST.ETS.CONFINT(A55,$B$2:$B$51,$A$2:$A$51,0.95,10,1) -> 12963.073 | E55: =C55+_xlfn.FORECAST.ETS.CONFINT(A55,$B$2:$B$51,$A$2:$A$51,0.95,10,1) -> 30900.661
A56: 45824 | C56: =_xlfn.FORECAST.ETS(A56,$B$2:$B$51,$A$2:$A$51,10,1) -> 21191.13 | D56: =C56-_xlfn.FORECAST.ETS.CONFINT(A56,$B$2:$B$51,$A$2:$A$51,0.95,10,1) -> 12222.175 | E56: =C56+_xlfn.FORECAST.ETS.CONFINT(A56,$B$2:$B$51,$A$2:$A$51,0.95,10,1) -> 30160.086
A57: 45831 | C57: =_xlfn.FORECAST.ETS(A57,$B$2:$B$51,$A$2:$A$51,10,1) -> 21634.279 | D57: =C57-_xlfn.FORECAST.ETS.CONFINT(A57,$B$2:$B$51,$A$2:$A$51,0.95,10,1) -> 12665.103 | E57: =C57+_xlfn.FORECAST.ETS.CONFINT(A57,$B$2:$B$51,$A$2:$A$51,0.95,10,1) -> 30603.454
A58: 45838 | C58: =_xlfn.FORECAST.ETS(A58,$B$2:$B$51,$A$2:$A$51,10,1) -> 16326.741 | D58: =C58-_xlfn.FORECAST.ETS.CONFINT(A58,$B$2:$B$51,$A$2:$A$51,0.95,10,1) -> 7357.2789 | E58: =C58+_xlfn.FORECAST.ETS.CONFINT(A58,$B$2:$B$51,$A$2:$A$51,0.95,10,1) -> 25296.204
A59: 45845 | C59: =_xlfn.FORECAST.ETS(A59,$B$2:$B$51,$A$2:$A$51,10,1) -> 20154.948 | D59: =C59-_xlfn.FORECAST.ETS.CONFINT(A59,$B$2:$B$51,$A$2:$A$51,0.95,10,1) -> 11185.122 | E59: =C59+_xlfn.FORECAST.ETS.CONFINT(A59,$B$2:$B$51,$A$2:$A$51,0.95,10,1) -> 29124.773
A60: 45852 | C60: =_xlfn.FORECAST.ETS(A60,$B$2:$B$51,$A$2:$A$51,10,1) -> 18501.23 | D60: =C60-_xlfn.FORECAST.ETS.CONFINT(A60,$B$2:$B$51,$A$2:$A$51,0.95,10,1) -> 9530.9558 | E60: =C60+_xlfn.FORECAST.ETS.CONFINT(A60,$B$2:$B$51,$A$2:$A$51,0.95,10,1) -> 27471.504
A61: 45859 | C61: =_xlfn.FORECAST.ETS(A61,$B$2:$B$51,$A$2:$A$51,10,1) -> 18340.072 | D61: =C61-_xlfn.FORECAST.ETS.CONFINT(A61,$B$2:$B$51,$A$2:$A$51,0.95,10,1) -> 9369.2552 | E61: =C61+_xlfn.FORECAST.ETS.CONFINT(A61,$B$2:$B$51,$A$2:$A$51,0.95,10,1) -> 27310.888
A62: 45866 | C62: =_xlfn.FORECAST.ETS(A62,$B$2:$B$51,$A$2:$A$51,10,1) -> 25075.226 | D62: =C62-_xlfn.FORECAST.ETS.CONFINT(A62,$B$2:$B$51,$A$2:$A$51,0.95,10,1) -> 16020.656 | E62: =C62+_xlfn.FORECAST.ETS.CONFINT(A62,$B$2:$B$51,$A$2:$A$51,0.95,10,1) -> 34129.796
A63: 45873 | C63: =_xlfn.FORECAST.ETS(A63,$B$2:$B$51,$A$2:$A$51,10,1) -> 25065.681 | D63: =C63-_xlfn.FORECAST.ETS.CONFINT(A63,$B$2:$B$51,$A$2:$A$51,0.95,10,1) -> 16010.36 | E63: =C63+_xlfn.FORECAST.ETS.CONFINT(A63,$B$2:$B$51,$A$2:$A$51,0.95,10,1) -> 34121.001
... A80: 45991 | C80: =_xlfn.FORECAST.ETS(A80,$B$2:$B$51,$A$2:$A$51,10,1) -> 18643.618 | D80: =C80-_xlfn.FORECAST.ETS.CONFINT(A80,$B$2:$B$51,$A$2:$A$51,0.95,10,1) -> 9457.6333 | E80: =C80+_xlfn.FORECAST.ETS.CONFINT(A80,$B$2:$B$51,$A$2:$A$51,0.95,10,1) -> 27829.603

Sheet Sheet37
A3: Row Labels | B3: Sum of NewFollower-Unfollower
A4: <03-06-2024 | B4: 0
A5: (blank) | B5: 0
A6: Jan | B6: 96295
A7: 45663 | B7: 27057
A8: 45670 | B8: 18737
A9: 45677 | B9: 27809
A10: 45684 | B10: 22692
A11: Feb | B11: 90480
A12: 45691 | B12: 28533
A13: 45698 | B13: 13642
A14: 45705 | B14: 17859
A15: 45712 | B15: 30446
A16: Mar | B16: 107259
A17: 45719 | B17: 20389
A18: 45726 | B18: 17807
A19: 45733 | B19: 28020
A20: 45740 | B20: 25416
A21: 45747 | B21: 15627
A22: Apr | B22: 85234
A23: 45754 | B23: 20720
A24: 45761 | B24: 24995
A25: 45768 | B25: 22070
A26: 45775 | B26: 17449
A27: May | B27: 34516
A28: 45782 | B28: 16129
A29: 45789 | B29: 18387
A30: Jun | B30: 104818
A31: 45446 | B31: 27203
A32: 45453 | B32: 23062
A33: 45460 | B33: 25931
A34: 45467 | B34: 28622
A35: Jul | B35: 101486
A36: 45474 | B36: 19833
A37: 45481 | B37: 18529
A38: 45488 | B38: 13885
A39: 45495 | B39: 32218
A40: 45502 | B40: 17021
A41: Aug | B41: 84848
A42: 45509 | B42: 14100
...

Sheet Task-6.3
A3: Correlate ad spend vs. follower growth using scatter plots.
A6: Month | B6: Average_Ad_Spend | C6: Average_Follower_Growth_Rate
A7: Jan | B7: 34258.938 | C7: 0.0073093713
A8: Feb | B8: 27614.625 | C8: 0.0061681378
A9: Mar | B9: 35630.1 | C9: 0.0052818011
A10: Apr | B10: 35863.062 | C10: 0.0047914534
A11: May | B11: 35986.625 | C11: 0.0036810534
A12: Jun | B12: 34480.25 | C12: 0.043724623
A13: Jul | B13: 34007 | C13: 0.01987337
A14: Aug | B14: 34065.375 | C14: 0.015153834
A15: Sep | B15: 33809.05 | C15: 0.011224688
A16: Oct | B16: 36221.5 | C16: 0.011432169
A17: Nov | B17: 40111.312 | C17: 0.0084963329
A18: Dec | B18: 34410.15 | C18: 0.0066673323
A20: Scatter plot chart is used to correlate ad spend and follower growth rate.
A21: Increase in June indicating that higher ad spend during that month significantly boosted follower growth.

Sheet Cleaned_Posts_Dataset
A1: PostID | B1: Platform | C1: Date | D1: ContentType | E1: Hashtags | F1: Likes | G1: Shares | H1: Comments | I1: Clicks | J1: Reach | K1: Impressions | L1: EngagementRate | M1: Campaign
A2: A82 | B2: LinkedIn | C2: 45497 | D2: Video | E2: #AppleMusic, #AppleLifestyle | F2: 22914 | G2: 954 | H2: 584 | I2: 1519 | J2: 13637 | K2: 49847 | L2: 0.49054106 | M2: Apple Watch Ultra 2 Launch
A3: A201 | B3: YouTube | C3: 45672 | D3: Tweet | E3: #ShotOniPhone | F3: 20360 | G3: 254 | H3: 726 | I3: 1995 | J3: 14280 | K3: 43726 | L3: 0.48803915 | M3: iPhone 16 Launch
A4: A121 | B4: LinkedIn | C4: 45502 | D4: Video | E4: #AppleWatchUltra2, #HealthTech | F4: 19144 | G4: 1182 | H4: 860 | I4: 1398 | J4: 4185 | K4: 46570 | L4: 0.45492807 | M4: Apple Watch Ultra 2 Launch
A5: A127 | B5: Twitter | C5: 45684 | D5: Image | E5: #AppleEvent, #iPhone16 | F5: 24415 | G5: 860 | H5: 931 | I5: 320 | J5: 65049 | K5: 62911 | L5: 0.41655672 | M5: Apple Watch Ultra 2 Launch
A6: A13 | B6: YouTube | C6: 45614 | D6: Carousel | E6: #AppleMusic, #AppleLifestyle | F6: 21255 | G6: 1452 | H6: 625 | I6: 1624 | J6: 21282 | K6: 57778 | L6: 0.40382152 | M6: MacBook Air M3 Campaign
A7: A123 | B7: Twitter | C7: 45457 | D7: Video | E7: #AppleEvent, #iPhone16 | F7: 17183 | G7: 1224 | H7: 943 | I7: 2010 | J7: 21481 | K7: 49110 | L7: 0.39401344 | M7: Sustainability Awareness Drive
A8: A287 | B8: Instagram | C8: 45519 | D8: Video | E8: #AppleEvent, #iPadPro | F8: 14977 | G8: 274 | H8: 798 | I8: 458 | J8: 6636 | K8: 43654 | L8: 0.367641 | M8: Apple Watch Ultra 2 Launch
A9: A226 | B9: Twitter | C9: 45908 | D9: Tweet | E9: #AppleWatch, #Health | F9: 23785 | G9: 1013 | H9: 468 | I9: 1628 | J9: 8272 | K9: 71348 | L9: 0.35412345 | M9: Apple Event September 2025
A10: A231 | B10: Twitter | C10: 45909 | D10: Image | E10: #AppleMusic, #AppleLifestyle | F10: 19260 | G10: 668 | H10: 994 | I10: 934 | J10: 20509 | K10: 61636 | L10: 0.33944448 | M10: Apple Event September 2025
A11: A185 | B11: Instagram | C11: 45668 | D11: Image | E11: #MacBookAirM3, #AppleInnovation | F11: 21181 | G11: 1242 | H11: 963 | I11: 1689 | J11: 49329 | K11: 69165 | L11: 0.33811899 | M11: Apple Watch Ultra 2 Launch
A12: A106 | B12: Twitter | C12: 45692 | D12: Carousel | E12: #AppleWatch, #Health | F12: 23833 | G12: 555 | H12: 523 | I12: 1330 | J12: 69141 | K12: 73997 | L12: 0.33664878 | M12: iPhone 16 Launch
A13: A174 | B13: LinkedIn | C13: 45465 | D13: Carousel | E13: #AppleWatchUltra2, #HealthTech | F13: 13479 | G13: 1189 | H13: 695 | I13: 416 | J13: 30229 | K13: 45704 | L13: 0.33614126 | M13: Apple Watch Ultra 2 Launch
... A301: A167 | B301: LinkedIn | C301: 45624 | D301: Carousel | E301: #AppleEvent, #iPhone16 | F301: 2302 | G301: 347 | H301: 642 | I301: 2175 | J301: 56378 | K301: 198056 | L301: 0.016616513 | M301: MacBook Air M3 Campaign

Sheet Sheet2
A1: Visualize Engagement vs. Ad Spend per platform.
A3: Row Labels | B3: Average of Engagement_Rate | C3: Average of Ad_Spend
A4: Instagram | B4: 0.15559292 | C4: 34821.235
A5: LinkedIn | B5: 0.14067998 | C5: 36191.327
A6: Twitter | B6: 0.17480513 | C6: 35360.057
A7: YouTube | B7: 0.17599263 | C7: 31374.902
A8: Grand Total | B8: 0.16076504 | C8: 34634.3
A10: This suggests that YouTube and Twitter deliver better engagement efficiency compared to other platforms.

Sheet Task-5.4
A3: Row Labels | B3: Average of Follower_Growth_Rate
A4: Apple Watch Ultra 2 Launch | B4: 0.0081853409
A5: iPhone 16 Launch | B5: 0.026400203
A6: MacBook Air M3 Campaign | B6: 0.011432169
A7: Sustainability Awareness Drive | B7: 0.0052818011
A8: Grand Total | B8: 0.013781836
A14: Pivot table and bar chart is used.
A15: The iPhone 16 Launch also drove the strongest follower growth at 2.64%

Sheet Cleaned_Engagement_Summary
A1: Week_Start_Date | B1: Platform | C1: New_Followers | D1: Unfollows | E1: Total_Followers | F1: Engagement_Rate_100 | G1: Engagement_Rate | H1: NewFollower-Unfollower | I1: Follower_Growth_Rate | J1: Campaign | K1: Ad_Spend
A2: 45446 | B2: Instagram | C2: 4138 | D2: 361 | E2: 103777 | F2: 56.637791 | G2: =F2/100 -> 0.56637791 | H2: 3777 | I2: 0.036395348 | J2: {=IFERROR(INDEX(Cleaned_Campaign_Metadata!A$2:A$6,MATCH(1,(A2 >= Cleaned_Campaign_Metadata!B$2:B$6) *(A2 <= Cleaned_Campaign_Metadata!C$2:C$6),0)),"")} | K2: 23944
A3: 45446 | B3: Twitter | C3: 8693 | D3: 1261 | E3: 111209 | F3: 69.475492 | G3: =F3/100 -> 0.69475492 | H3: 7432 | I3: 0.066829124 | J3: {=IFERROR(INDEX(Cleaned_Campaign_Metadata!A$2:A$6,MATCH(1,(A3 >= Cleaned_Campaign_Metadata!B$2:B$6) *(A3 <= Cleaned_Campaign_Metadata!C$2:C$6),0)),"")} | K3: 29873
A4: 45446 | B4: YouTube | C4: 9264 | D4: 1141 | E4: 119332 | F4: 92.312205 | G4: =F4/100 -> 0.92312205 | H4: 8123 | I4: 0.068070593 | J4: {=IFERROR(INDEX(Cleaned_Campaign_Metadata!A$2:A$6,MATCH(1,(A4 >= Cleaned_Campaign_Metadata!B$2:B$6) *(A4 <= Cleaned_Campaign_Metadata!C$2:C$6),0)),"")} | K4: 50372
A5: 45446 | B5: YouTube | C5: 8842 | D5: 971 | E5: 127203 | F5: 16.351816 | G5: =F5/100 -> 0.16351816 | H5: 7871 | I5: 0.061877471 | J5: {=IFERROR(INDEX(Cleaned_Campaign_Metadata!A$2:A$6,MATCH(1,(A5 >= Cleaned_Campaign_Metadata!B$2:B$6) *(A5 <= Cleaned_Campaign_Metadata!C$2:C$6),0)),"")} | K5: 33928
A6: 45453 | B6: Instagram | C6: 7721 | D6: 506 | E6: 134418 | F6: 35.577824 | G6: =F6/100 -> 0.35577824 | H6: 7215 | I6: 0.053675847 | J6: {=IFERROR(INDEX(Cleaned_Campaign_Metadata!A$2:A$6,MATCH(1,(A6 >= Cleaned_Campaign_Metadata!B$2:B$6) *(A6 <= Cleaned_Campaign_Metadata!C$2:C$6),0)),"")} | K6: 25379
A7: 45453 | B7: Twitter | C7: 5225 | D7: 291 | E7: 146830 | F7: 19.551863 | G7: =F7/100 -> 0.19551863 | H7: 4934 | I7: 0.033603487 | J7: {=IFERROR(INDEX(Cleaned_Campaign_Metadata!A$2:A$6,MATCH(1,(A7 >= Cleaned_Campaign_Metadata!B$2:B$6) *(A7 <= Cleaned_Campaign_Metadata!C$2:C$6),0)),"")} | K7: 44546
A8: 45453 | B8: Twitter | C8: 3978 | D8: 543 | E8: 150265 | F8: 49.159818 | G8: =F8/100 -> 0.49159818 | H8: 3435 | I8: 0.022859615 | J8: {=IFERROR(INDEX(Cleaned_Campaign_Metadata!A$2:A$6,MATCH(1,(A8 >= Cleaned_Campaign_Metadata!B$2:B$6) *(A8 <= Cleaned_Campaign_Metadata!C$2:C$6),0)),"")} | K8: 34286
A9: 45453 | B9: YouTube | C9: 8002 | D9: 524 | E9: 141896 | F9: 52.064893 | G9: =F9/100 -> 0.52064893 | H9: 7478 | I9: 0.052700569 | J9: {=IFERROR(INDEX(Cleaned_Campaign_Metadata!A$2:A$6,MATCH(1,(A9 >= Cleaned_Campaign_Metadata!B$2:B$6) *(A9 <= Cleaned_Campaign_Metadata!C$2:C$6),0)),"")} | K9: 46751
A10: 45460 | B10: Instagram | C10: 8373 | D10: 921 | E10: 157717 | F10: 12.226329 | G10: =F10/100 -> 0.12226329 | H10: 7452 | I10: 0.047249187 | J10: {=IFERROR(INDEX(Cleaned_Campaign_Metadata!A$2:A$6,MATCH(1,(A10 >= Cleaned_Campaign_Metadata!B$2:B$6) *(A10 <= Cleaned_Campaign_Metadata!C$2:C$6),0)),"")} -> iPhone 16 Launch | K10: 15110
A11: 45460 | B11: Instagram | C11: 6656 | D11: 978 | E11: 176196 | F11: 60.425889 | G11: =F11/100 -> 0.60425889 | H11: 5678 | I11: 0.032225476 | J11: {=IFERROR(INDEX(Cleaned_Campaign_Metadata!A$2:A$6,MATCH(1,(A11 >= Cleaned_Campaign_Metadata!B$2:B$6) *(A11 <= Cleaned_Campaign_Metadata!C$2:C$6),0)),"")} -> iPhone 16 Launch | K11: 27081
A12: 45460 | B12: LinkedIn | C12: 7097 | D12: 369 | E12: 170518 | F12: 9.2506363 | G12: =F12/100 -> 0.092506363 | H12: 6728 | I12: 0.039456245 | J12: {=IFERROR(INDEX(Cleaned_Campaign_Metadata!A$2:A$6,MATCH(1,(A12 >= Cleaned_Campaign_Metadata!B$2:B$6) *(A12 <= Cleaned_Campaign_Metadata!C$2:C$6),0)),"")} -> iPhone 16 Launch | K12: 33762
A13: 45460 | B13: Twitter | C13: 6907 | D13: 834 | E13: 163790 | F13: 54.158984 | G13: =F13/100 -> 0.54158984 | H13: 6073 | I13: 0.037077966 | J13: {=IFERROR(INDEX(Cleaned_Campaign_Metadata!A$2:A$6,MATCH(1,(A13 >= Cleaned_Campaign_Metadata!B$2:B$6) *(A13 <= Cleaned_Campaign_Metadata!C$2:C$6),0)),"")} -> iPhone 16 Launch | K13: 22087
... A201: 45789 | B201: Twitter | C201: 8527 | D201: 1091 | E201: 1186398 | F201: 1.6760817 | G201: =F201/100 -> 0.016760817 | H201: 7436 | I201: 0.0062677112 | J201: {=IFERROR(INDEX(Cleaned_Campaign_Metadata!A$2:A$6,MATCH(1,(A201 >= Cleaned_Campaign_Metadata!B$2:B$6) *(A201 <= Cleaned_Campaign_Metadata!C$2:C$6),0)),"")} | K201: 41703

Sheet Posts
A1: PostID | B1: Platform | C1: Date | D1: ContentType | E1: Hashtags | F1: Likes | G1: Shares | H1: Comments | I1: Clicks | J1: Reach | K1: Impressions | L1: EngagementRate | M1: Campaign
A2: A82 | B2: LinkedIn | C2: 45497 | D2: Video | E2: #AppleMusic, #AppleLifestyle | F2: 22914 | G2: 954 | H2: 584 | I2: 1519 | J2: 13637 | K2: 49847 | L2: =(F2+G2+H2)/K2 -> 0.49054106 | M2: Apple Watch Ultra 2 Launch
A3: A201 | B3: YouTube | C3: 45672 | D3: Tweet | E3: #ShotOniPhone | F3: 20360 | G3: 254 | H3: 726 | I3: 1995 | J3: 14280 | K3: 43726 | L3: =(F3+G3+H3)/K3 -> 0.48803915 | M3: iPhone 16 Launch
A4: A121 | B4: LinkedIn | C4: 45502 | D4: Video | E4: #AppleWatchUltra2, #HealthTech | F4: 19144 | G4: 1182 | H4: 860 | I4: 1398 | J4: 4185 | K4: 46570 | L4: =(F4+G4+H4)/K4 -> 0.45492807 | M4: Apple Watch Ultra 2 Launch
A5: A127 | B5: Twitter | C5: 45684 | D5: Image | E5: #AppleEvent, #iPhone16 | F5: 24415 | G5: 860 | H5: 931 | I5: 320 | J5: 65049 | K5: 62911 | L5: =(F5+G5+H5)/K5 -> 0.41655672 | M5: Apple Watch Ultra 2 Launch
A6: A13 | B6: YouTube | C6: 45614 | D6: Carousel | E6: #AppleMusic, #AppleLifestyle | F6: 21255 | G6: 1452 | H6: 625 | I6: 1624 | J6: 21282 | K6: 57778 | L6: =(F6+G6+H6)/K6 -> 0.40382152 | M6: MacBook Air M3 Campaign
A7: A123 | B7: Twitter | C7: 45457 | D7: Video | E7: #AppleEvent, #iPhone16 | F7: 17183 | G7: 1224 | H7: 943 | I7: 2010 | J7: 21481 | K7: 49110 | L7: =(F7+G7+H7)/K7 -> 0.39401344 | M7: Sustainability Awareness Drive
A8: A287 | B8: Instagram | C8: 45519 | D8: Video | E8: #AppleEvent, #iPadPro | F8: 14977 | G8: 274 | H8: 798 | I8: 458 | J8: 6636 | K8: 43654 | L8: =(F8+G8+H8)/K8 -> 0.367641 | M8: Apple Watch Ultra 2 Launch
A9: A226 | B9: Twitter | C9: 45908 | D9: Tweet | E9: #AppleWatch, #Health | F9: 23785 | G9: 1013 | H9: 468 | I9: 1628 | J9: 8272 | K9: 71348 | L9: =(F9+G9+H9)/K9 -> 0.35412345 | M9: Apple Event September 2025
A10: A231 | B10: Twitter | C10: 45909 | D10: Image | E10: #AppleMusic, #AppleLifestyle | F10: 19260 | G10: 668 | H10: 994 | I10: 934 | J10: 20509 | K10: 61636 | L10: =(F10+G10+H10)/K10 -> 0.33944448 | M10: Apple Event September 2025
A11: A185 | B11: Instagram | C11: 45668 | D11: Image | E11: #MacBookAirM3, #AppleInnovation | F11: 21181 | G11: 1242 | H11: 963 | I11: 1689 | J11: 49329 | K11: 69165 | L11: =(F11+G11+H11)/K11 -> 0.33811899 | M11: Apple Watch Ultra 2 Launch
A12: A106 | B12: Twitter | C12: 45692 | D12: Carousel | E12: #AppleWatch, #Health | F12: 23833 | G12: 555 | H12: 523 | I12: 1330 | J12: 69141 | K12: 73997 | L12: =(F12+G12+H12)/K12 -> 0.33664878 | M12: iPhone 16 Launch
A13: A174 | B13: LinkedIn | C13: 45465 | D13: Carousel | E13: #AppleWatchUltra2, #HealthTech | F13: 13479 | G13: 1189 | H13: 695 | I13: 416 | J13: 30229 | K13: 45704 | L13: =(F13+G13+H13)/K13 -> 0.33614126 | M13: Apple Watch Ultra 2 Launch
... A301: A167 | B301: LinkedIn | C301: 45624 | D301: Carousel | E301: #AppleEvent, #iPhone16 | F301: 2302 | G301: 347 | H301: 642 | I301: 2175 | J301: 56378 | K301: 198056 | L301: =(F301+G301+H301)/K301 -> 0.016616513 | M301: MacBook Air M3 Campaign

Sheet Sheet12
A3: Platform | B3: Sum of Follower_Growth_Rate
A4: Instagram | B4: 0.613565
A5: LinkedIn | B5: 0.51857546
A6: Twitter | B6: 0.72951117
A7: YouTube | B7: 0.58195538
A8: (blank) | B8: #DIV/0!
A9: Grand Total | B9: #DIV/0!

Sheet Engagement Summary
A1: Week_Start_Date | B1: Platform | C1: New_Followers | D1: Unfollows | E1: Total_Followers | F1: Engagement_Rate | G1: NewFollower-Unfollower | H1: Follower_Growth_Rate | I1: F_Growth_rate | J1: Ad_Spend
A2: 45446 | B2: Instagram | C2: 4138 | D2: 361 | E2: 103777 | F2: 56.637791 | G2: =C2-D2 -> 3777 | H2: =(C2-D2)/E2 -> 0.036395348 | I2: =(C2 - D2) / (E2 - C2) -> 0.037906844 | J2: 23944
A3: 45453 | B3: Instagram | C3: 7721 | D3: 506 | E3: 134418 | F3: 35.577824 | G3: =C3-D3 -> 7215 | H3: =(C3-D3)/E3 -> 0.053675847 | I3: =(C3 - D3) / (E3 - C3) -> 0.056946889 | J3: 25379
A4: 45460 | B4: Instagram | C4: 8373 | D4: 921 | E4: 157717 | F4: 12.226329 | G4: =C4-D4 -> 7452 | H4: =(C4-D4)/E4 -> 0.047249187 | I4: =(C4 - D4) / (E4 - C4) -> 0.049898222 | J4: 15110
A5: 45460 | B5: Instagram | C5: 6656 | D5: 978 | E5: 176196 | F5: 60.425889 | G5: =C5-D5 -> 5678 | H5: =(C5-D5)/E5 -> 0.032225476 | I5: =(C5 - D5) / (E5 - C5) -> 0.033490622 | J5: 27081
A6: 45467 | B6: Instagram | C6: 5259 | D6: 374 | E6: 189735 | F6: 14.827523 | G6: =C6-D6 -> 4885 | H6: =(C6-D6)/E6 -> 0.025746436 | I6: =(C6 - D6) / (E6 - C6) -> 0.026480409 | J6: 19596
A7: 45474 | B7: Instagram | C7: 3530 | D7: 328 | E7: 221925 | F7: 12.83722 | G7: =C7-D7 -> 3202 | H7: =(C7-D7)/E7 -> 0.014428298 | I7: =(C7 - D7) / (E7 - C7) -> 0.014661508 | J7: 11013
A8: 45474 | B8: Instagram | C8: 2960 | D8: 234 | E8: 224651 | F8: 17.412787 | G8: =C8-D8 -> 2726 | H8: =(C8-D8)/E8 -> 0.012134377 | I8: =(C8 - D8) / (E8 - C8) -> 0.012296395 | J8: 59378
A9: 45488 | B9: Instagram | C9: 3964 | D9: 378 | E9: 246766 | F9: 13.63559 | G9: =C9-D9 -> 3586 | H9: =(C9-D9)/E9 -> 0.014531986 | I9: =(C9 - D9) / (E9 - C9) -> 0.014769236 | J9: 23109
A10: 45488 | B10: Instagram | C10: 1536 | D10: 155 | E10: 257065 | F10: 12.157626 | G10: =C10-D10 -> 1381 | H10: =(C10-D10)/E10 -> 0.0053721821 | I10: =(C10 - D10) / (E10 - C10) -> 0.0054044746 | J10: 36661
A11: 45509 | B11: Instagram | C11: 3494 | D11: 281 | E11: 309517 | F11: 27.765519 | G11: =C11-D11 -> 3213 | H11: =(C11-D11)/E11 -> 0.01038069 | I11: =(C11 - D11) / (E11 - C11) -> 0.010499211 | J11: 39197
A12: 45516 | B12: Instagram | C12: 7610 | D12: 757 | E12: 333052 | F12: 44.450416 | G12: =C12-D12 -> 6853 | H12: =(C12-D12)/E12 -> 0.020576366 | I12: =(C12 - D12) / (E12 - C12) -> 0.021057516 | J12: 39750
A13: 45523 | B13: Instagram | C13: 7488 | D13: 568 | E13: 354010 | F13: 13.477303 | G13: =C13-D13 -> 6920 | H13: =(C13-D13)/E13 -> 0.01954747 | I13: =(C13 - D13) / (E13 - C13) -> 0.019969872 | J13: 46727
... A201: 45782 | B201: YouTube | C201: 5875 | D201: 665 | E201: 1157985 | F201: 6.9871371 | G201: =C201-D201 -> 5210 | H201: =(C201-D201)/E201 -> 0.0044991947 | I201: =(C201 - D201) / (E201 - C201) -> 0.0045221376 | J201: 32669
G202: =C202-D202 -> 0 | H202: =(C202-D202)/E202 -> #DIV/0! | I202: =(C202 - D202) / (E202 - C202) -> #DIV/0!
G203: =C203-D203 -> 0 | H203: =(C203-D203)/E203 -> #DIV/0! | I203: =(C203 - D203) / (E203 - C203) -> #DIV/0!
G204: =C204-D204 -> 0 | H204: =(C204-D204)/E204 -> #DIV/0! | I204: =(C204 - D204) / (E204 - C204) -> #DIV/0!
G205: =C205-D205 -> 0 | H205: =(C205-D205)/E205 -> #DIV/0! | I205: =(C205 - D205) / (E205 - C205) -> #DIV/0!
G206: =C206-D206 -> 0 | H206: =(C206-D206)/E206 -> #DIV/0! | I206: =(C206 - D206) / (E206 - C206) -> #DIV/0!
G207: =C207-D207 -> 0 | H207: =(C207-D207)/E207 -> #DIV/0! | I207: =(C207 - D207) / (E207 - C207) -> #DIV/0!
